Workbook

Sheet All_Top_5
A1: Protein_name | B1: Target_group | C1: Uniprot_id | D1: Target_name | E1: Target_type | F1: Complex_participants | G1: intracluster_score | H1: intercluster_score | I1: Conectivity_score | J1: Source | K1: Cluster
A2: FUCA1 | B2: =VLOOKUP(Tabla6[[#This Row],[Protein_name]],raw!$A$2:$F$5391,6,FALSE) -> T4 | C2: =VLOOKUP(Tabla6[[#This Row],[Protein_name]],raw!$A$2:$F$5391,4,FALSE) -> P04066 | D2: =VLOOKUP(Tabla6[[#This Row],[Protein_name]],raw!$A$2:$F$5391,2,FALSE) -> tissue alpha-l-fucosidase (ec 3.2.1.51) (alpha-l-fucosidase i) (alpha-l-fucoside fucohydrolase 1) (alpha-l-fucosidase 1) | E2: =VLOOKUP(Tabla6[[#This Row],[Protein_name]],raw!$A$2:$F$5391,5,FALSE) -> SINGLE PROTEIN | F2: =VLOOKUP(Tabla6[[#This Row],[Protein_name]],raw!$A$2:$F$5391,3,FALSE) -> 0 | G2: =VLOOKUP(Tabla6[[#This Row],[Protein_name]],T4_metrics!$A$2:$G$693,4,FALSE) -> 6.779 | H2: =VLOOKUP(Tabla6[[#This Row],[Protein_name]],T4_metrics!$A$2:$G$693,5,FALSE) -> 1.598 | I2: =VLOOKUP(Tabla6[[#This Row],[Protein_name]],T4_metrics!$A$2:$G$693,6,FALSE) -> 0.74878415 | J2: Connectivity | K2: 0
A3: IDUA | B3: =VLOOKUP(Tabla6[[#This Row],[Protein_name]],raw!$A$2:$F$5391,6,FALSE) -> T4 | C3: =VLOOKUP(Tabla6[[#This Row],[Protein_name]],raw!$A$2:$F$5391,4,FALSE) -> P35475 | D3: =VLOOKUP(Tabla6[[#This Row],[Protein_name]],raw!$A$2:$F$5391,2,FALSE) -> alpha-l-iduronidase (ec 3.2.1.76) | E3: =VLOOKUP(Tabla6[[#This Row],[Protein_name]],raw!$A$2:$F$5391,5,FALSE) -> SINGLE PROTEIN | F3: =VLOOKUP(Tabla6[[#This Row],[Protein_name]],raw!$A$2:$F$5391,3,FALSE) -> 0 | G3: =VLOOKUP(Tabla6[[#This Row],[Protein_name]],T4_metrics!$A$2:$G$693,4,FALSE) -> 8.268 | H3: =VLOOKUP(Tabla6[[#This Row],[Protein_name]],T4_metrics!$A$2:$G$693,5,FALSE) -> 0.448 | I3: =VLOOKUP(Tabla6[[#This Row],[Protein_name]],T4_metrics!$A$2:$G$693,6,FALSE) -> 0.72258046 | J3: Connectivity | K3: 0
A4: NEU1 | B4: =VLOOKUP(Tabla6[[#This Row],[Protein_name]],raw!$A$2:$F$5391,6,FALSE) -> T4 | C4: =VLOOKUP(Tabla6[[#This Row],[Protein_name]],raw!$A$2:$F$5391,4,FALSE) -> Q99519 | D4: =VLOOKUP(Tabla6[[#This Row],[Protein_name]],raw!$A$2:$F$5391,2,FALSE) -> sialidase-1 (ec 3.2.1.18) (acetylneuraminyl hydrolase) (g9 sialidase) (lysosomal sialidase) (n-acetyl-alpha-neuraminidase 1) | E4: =VLOOKUP(Tabla6[[#This Row],[Protein_name]],raw!$A$2:$F$5391,5,FALSE) -> SINGLE PROTEIN | F4: =VLOOKUP(Tabla6[[#This Row],[Protein_name]],raw!$A$2:$F$5391,3,FALSE) -> 0 | G4: =VLOOKUP(Tabla6[[#This Row],[Protein_name]],T4_metrics!$A$2:$G$693,4,FALSE) -> 4.565 | H4: =VLOOKUP(Tabla6[[#This Row],[Protein_name]],T4_metrics!$A$2:$G$693,5,FALSE) -> 0 | I4: =VLOOKUP(Tabla6[[#This Row],[Protein_name]],T4_metrics!$A$2:$G$693,6,FALSE) -> 0.70894846 | J4: Connectivity | K4: 0
A5: MAN2B1 | B5: =VLOOKUP(Tabla6[[#This Row],[Protein_name]],raw!$A$2:$F$5391,6,FALSE) -> T4 | C5: =VLOOKUP(Tabla6[[#This Row],[Protein_name]],raw!$A$2:$F$5391,4,FALSE) -> O00754 | D5: =VLOOKUP(Tabla6[[#This Row],[Protein_name]],raw!$A$2:$F$5391,2,FALSE) -> lysosomal alpha-mannosidase (laman) (ec 3.2.1.24) (lysosomal acid alpha-mannosidase) (mannosidase alpha class 2b member 1) (mannosidase alpha-b) [cleaved into: lysosomal alpha-mannosidase a peptide; lysosomal alpha-mannosidase b peptide; lysosomal alpha-mannosidase c peptide; lysosomal alpha-mannosidase d peptide; lysosomal alpha-mannosidase e peptide] | E5: =VLOOKUP(Tabla6[[#This Row],[Protein_name]],raw!$A$2:$F$5391,5,FALSE) -> SINGLE PROTEIN | F5: =VLOOKUP(Tabla6[[#This Row],[Protein_name]],raw!$A$2:$F$5391,3,FALSE) -> 0 | G5: =VLOOKUP(Tabla6[[#This Row],[Protein_name]],T4_metrics!$A$2:$G$693,4,FALSE) -> 6.809 | H5: =VLOOKUP(Tabla6[[#This Row],[Protein_name]],T4_metrics!$A$2:$G$693,5,FALSE) -> 0 | I5: =VLOOKUP(Tabla6[[#This Row],[Protein_name]],T4_metrics!$A$2:$G$693,6,FALSE) -> 0.70880052 | J5: Connectivity | K5: 0
A6: NAGLU | B6: =VLOOKUP(Tabla6[[#This Row],[Protein_name]],raw!$A$2:$F$5391,6,FALSE) -> T4 | C6: =VLOOKUP(Tabla6[[#This Row],[Protein_name]],raw!$A$2:$F$5391,4,FALSE) -> P54802 | D6: =VLOOKUP(Tabla6[[#This Row],[Protein_name]],raw!$A$2:$F$5391,2,FALSE) -> alpha-n-acetylglucosaminidase (ec 3.2.1.50) (n-acetyl-alpha-glucosaminidase) (nag) [cleaved into: alpha-n-acetylglucosaminidase 82 kda form; alpha-n-acetylglucosaminidase 77 kda form] | E6: =VLOOKUP(Tabla6[[#This Row],[Protein_name]],raw!$A$2:$F$5391,5,FALSE) -> SINGLE PROTEIN | F6: =VLOOKUP(Tabla6[[#This Row],[Protein_name]],raw!$A$2:$F$5391,3,FALSE) -> 0 | G6: =VLOOKUP(Tabla6[[#This Row],[Protein_name]],T4_metrics!$A$2:$G$693,4,FALSE) -> 10.574 | H6: =VLOOKUP(Tabla6[[#This Row],[Protein_name]],T4_metrics!$A$2:$G$693,5,FALSE) -> 0 | I6: =VLOOKUP(Tabla6[[#This Row],[Protein_name]],T4_metrics!$A$2:$G$693,6,FALSE) -> 0.6790441 | J6: Connectivity | K6: 0
A7: CPX-5675 | B7: =VLOOKUP(Tabla6[[#This Row],[Protein_name]],raw!$A$2:$F$5391,6,FALSE) -> T4 | C7: =VLOOKUP(Tabla6[[#This Row],[Protein_name]],raw!$A$2:$F$5391,4,FALSE) -> P06681, P0C0L4, P0C0L4, P0C0L4 | D7: =VLOOKUP(Tabla6[[#This Row],[Protein_name]],raw!$A$2:$F$5391,2,FALSE) -> complement c2 (ec 3.4.21.43) (c3/c5 convertase) [cleaved into: complement c2b fragment; complement c2a fragment] | E7: =VLOOKUP(Tabla6[[#This Row],[Protein_name]],raw!$A$2:$F$5391,5,FALSE) -> PROTEIN COMPLEX | F7: =VLOOKUP(Tabla6[[#This Row],[Protein_name]],raw!$A$2:$F$5391,3,FALSE) -> P06681-PRO_0000027612,P0C0L4-PRO_0000005970,P0C0L4-PRO_0000005966,P0C0L4-PRO_0000005972 | G7: =VLOOKUP(Tabla6[[#This Row],[Protein_name]],T4_metrics!$A$2:$G$693,4,FALSE) -> 23.405 | H7: =VLOOKUP(Tabla6[[#This Row],[Protein_name]],T4_metrics!$A$2:$G$693,5,FALSE) -> 0.865 | I7: =VLOOKUP(Tabla6[[#This Row],[Protein_name]],T4_metrics!$A$2:$G$693,6,FALSE) -> 1.5475136 | J7: Connectivity | K7: 1
A8: CPX-6215 | B8: =VLOOKUP(Tabla6[[#This Row],[Protein_name]],raw!$A$2:$F$5391,6,FALSE) -> T4 | C8: =VLOOKUP(Tabla6[[#This Row],[Protein_name]],raw!$A$2:$F$5391,4,FALSE) -> P00742, P00742 | D8: =VLOOKUP(Tabla6[[#This Row],[Protein_name]],raw!$A$2:$F$5391,2,FALSE) -> coagulation factor x (ec 3.4.21.6) (stuart factor) (stuart-prower factor) [cleaved into: factor x light chain; factor x heavy chain; activated factor xa heavy chain] | E8: =VLOOKUP(Tabla6[[#This Row],[Protein_name]],raw!$A$2:$F$5391,5,FALSE) -> PROTEIN COMPLEX | F8: =VLOOKUP(Tabla6[[#This Row],[Protein_name]],raw!$A$2:$F$5391,3,FALSE) -> P00742-PRO_0000027789,P00742-PRO_0000027788 | G8: =VLOOKUP(Tabla6[[#This Row],[Protein_name]],T4_metrics!$A$2:$G$693,4,FALSE) -> 19.108 | H8: =VLOOKUP(Tabla6[[#This Row],[Protein_name]],T4_metrics!$A$2:$G$693,5,FALSE) -> 0.941 | I8: =VLOOKUP(Tabla6[[#This Row],[Protein_name]],T4_metrics!$A$2:$G$693,6,FALSE) -> 1.4572379 | J8: Connectivity | K8: 1
A9: CPX-6234 | B9: =VLOOKUP(Tabla6[[#This Row],[Protein_name]],raw!$A$2:$F$5391,6,FALSE) -> T4 | C9: =VLOOKUP(Tabla6[[#This Row],[Protein_name]],raw!$A$2:$F$5391,4,FALSE) -> P03952, P03952 | D9: =VLOOKUP(Tabla6[[#This Row],[Protein_name]],raw!$A$2:$F$5391,2,FALSE) -> plasma kallikrein (ec 3.4.21.34) (fletcher factor) (kininogenin) (plasma prekallikrein) (pkk) [cleaved into: plasma kallikrein heavy chain; plasma kallikrein light chain] | E9: =VLOOKUP(Tabla6[[#This Row],[Protein_name]],raw!$A$2:$F$5391,5,FALSE) -> PROTEIN COMPLEX | F9: =VLOOKUP(Tabla6[[#This Row],[Protein_name]],raw!$A$2:$F$5391,3,FALSE) -> P03952-PRO_0000028022,P03952-PRO_0000028021 | G9: =VLOOKUP(Tabla6[[#This Row],[Protein_name]],T4_metrics!$A$2:$G$693,4,FALSE) -> 17.858 | H9: =VLOOKUP(Tabla6[[#This Row],[Protein_name]],T4_metrics!$A$2:$G$693,5,FALSE) -> 1.081 | I9: =VLOOKUP(Tabla6[[#This Row],[Protein_name]],T4_metrics!$A$2:$G$693,6,FALSE) -> 1.4558477 | J9: Connectivity | K9: 1
A10: CPX-4945 | B10: =VLOOKUP(Tabla6[[#This Row],[Protein_name]],raw!$A$2:$F$5391,6,FALSE) -> T4 | C10: =VLOOKUP(Tabla6[[#This Row],[Protein_name]],raw!$A$2:$F$5391,4,FALSE) -> P00740, P00740 | D10: =VLOOKUP(Tabla6[[#This Row],[Protein_name]],raw!$A$2:$F$5391,2,FALSE) -> coagulation factor ix (ec 3.4.21.22) (christmas factor) (plasma thromboplastin component) (ptc) [cleaved into: coagulation factor ixa light chain; coagulation factor ixa heavy chain] | E10: =VLOOKUP(Tabla6[[#This Row],[Protein_name]],raw!$A$2:$F$5391,5,FALSE) -> PROTEIN COMPLEX | F10: =VLOOKUP(Tabla6[[#This Row],[Protein_name]],raw!$A$2:$F$5391,3,FALSE) -> P00740-PRO_0000027757,P00740-PRO_0000027759 | G10: =VLOOKUP(Tabla6[[#This Row],[Protein_name]],T4_metrics!$A$2:$G$693,4,FALSE) -> 19.111 | H10: =VLOOKUP(Tabla6[[#This Row],[Protein_name]],T4_metrics!$A$2:$G$693,5,FALSE) -> 4.126 | I10: =VLOOKUP(Tabla6[[#This Row],[Protein_name]],T4_metrics!$A$2:$G$693,6,FALSE) -> 1.3763838 | J10: Connectivity | K10: 1
A11: CPX-6224 | B11: =VLOOKUP(Tabla6[[#This Row],[Protein_name]],raw!$A$2:$F$5391,6,FALSE) -> T4 | C11: =VLOOKUP(Tabla6[[#This Row],[Protein_name]],raw!$A$2:$F$5391,4,FALSE) -> P04070, P04070 | D11: =VLOOKUP(Tabla6[[#This Row],[Protein_name]],raw!$A$2:$F$5391,2,FALSE) -> vitamin k-dependent protein c (ec 3.4.21.69) (anticoagulant protein c) (autoprothrombin iia) (blood coagulation factor xiv) [cleaved into: vitamin k-dependent protein c light chain; vitamin k-dependent protein c heavy chain; activation peptide] | E11: =VLOOKUP(Tabla6[[#This Row],[Protein_name]],raw!$A$2:$F$5391,5,FALSE) -> PROTEIN COMPLEX | F11: =VLOOKUP(Tabla6[[#This Row],[Protein_name]],raw!$A$2:$F$5391,3,FALSE) -> P04070-PRO_0000028110,P04070-PRO_0000028109 | G11: =VLOOKUP(Tabla6[[#This Row],[Protein_name]],T4_metrics!$A$2:$G$693,4,FALSE) -> 16.428 | H11: =VLOOKUP(Tabla6[[#This Row],[Protein_name]],T4_metrics!$A$2:$G$693,5,FALSE) -> 0 | I11: =VLOOKUP(Tabla6[[#This Row],[Protein_name]],T4_metrics!$A$2:$G$693,6,FALSE) -> 1.3505542 | J11: Connectivity | K11: 1
A12: NRL | B12: =VLOOKUP(Tabla6[[#This Row],[Protein_name]],raw!$A$2:$F$5391,6,FALSE) -> T4 | C12: =VLOOKUP(Tabla6[[#This Row],[Protein_name]],raw!$A$2:$F$5391,4,FALSE) -> P54845 | D12: =VLOOKUP(Tabla6[[#This Row],[Protein_name]],raw!$A$2:$F$5391,2,FALSE) -> neural retina-specific leucine zipper protein (nrl) | E12: =VLOOKUP(Tabla6[[#This Row],[Protein_name]],raw!$A$2:$F$5391,5,FALSE) -> SINGLE PROTEIN | F12: =VLOOKUP(Tabla6[[#This Row],[Protein_name]],raw!$A$2:$F$5391,3,FALSE) -> 0 | G12: =VLOOKUP(Tabla6[[#This Row],[Protein_name]],T4_metrics!$A$2:$G$693,4,FALSE) -> 28.493 | H12: =VLOOKUP(Tabla6[[#This Row],[Protein_name]],T4_metrics!$A$2:$G$693,5,FALSE) -> 0.553 | I12: =VLOOKUP(Tabla6[[#This Row],[Protein_name]],T4_metrics!$A$2:$G$693,6,FALSE) -> 0.77451374 | J12: Connectivity | K12: 2
A13: GUCY2D | B13: =VLOOKUP(Tabla6[[#This Row],[Protein_name]],raw!$A$2:$F$5391,6,FALSE) -> T4 | C13: =VLOOKUP(Tabla6[[#This Row],[Protein_name]],raw!$A$2:$F$5391,4,FALSE) -> Q02846 | D13: =VLOOKUP(Tabla6[[#This Row],[Protein_name]],raw!$A$2:$F$5391,2,FALSE) -> retinal guanylyl cyclase 1 (retgc-1) (ec 4.6.1.2) (cg-e) (guanylate cyclase 2d, retinal) (rod outer segment membrane guanylate cyclase) (ros-gc) | E13: =VLOOKUP(Tabla6[[#This Row],[Protein_name]],raw!$A$2:$F$5391,5,FALSE) -> SINGLE PROTEIN | F13: =VLOOKUP(Tabla6[[#This Row],[Protein_name]],raw!$A$2:$F$5391,3,FALSE) -> 0 | G13: =VLOOKUP(Tabla6[[#This Row],[Protein_name]],T4_metrics!$A$2:$G$693,4,FALSE) -> 33.858 | H13: =VLOOKUP(Tabla6[[#This Row],[Protein_name]],T4_metrics!$A$2:$G$693,5,FALSE) -> 2.511 | I13: =VLOOKUP(Tabla6[[#This Row],[Protein_name]],T4_metrics!$A$2:$G$693,6,FALSE) -> 0.73510789 | J13: Connectivity | K13: 2
... A181: CPX-7519 | B181: =VLOOKUP(Tabla6[[#This Row],[Protein_name]],raw!$A$2:$F$5391,6,FALSE) -> T4 | C181: =VLOOKUP(Tabla6[[#This Row],[Protein_name]],raw!$A$2:$F$5391,4,FALSE) -> P35227, Q99496, Q14781, P78364 | D181: =VLOOKUP(Tabla6[[#This Row],[Protein_name]],raw!$A$2:$F$5391,2,FALSE) -> chromobox protein homolog 2 | E181: =VLOOKUP(Tabla6[[#This Row],[Protein_name]],raw!$A$2:$F$5391,5,FALSE) -> PROTEIN COMPLEX | F181: =VLOOKUP(Tabla6[[#This Row],[Protein_name]],raw!$A$2:$F$5391,3,FALSE) -> PCGF2,RNF2,CBX2,PHC1 | G181: =VLOOKUP(Tabla6[[#This Row],[Protein_name]],T4_metrics!$A$2:$G$693,4,FALSE) -> 108.916 | H181: =VLOOKUP(Tabla6[[#This Row],[Protein_name]],T4_metrics!$A$2:$G$693,5,FALSE) -> 40.809 | I181: =VLOOKUP(Tabla6[[#This Row],[Protein_name]],T4_metrics!$A$2:$G$693,6,FALSE) -> 0.93053891 | J181: Intracluster | K181: 11

Sheet connectivity
A1: protein_name | B1: Clúster | C1: connectivity_score | D1: go_term
A2: FUCA1 | B2: 0 | C2: 0.74878415 | D2: Lysosomal Lumen
A3: IDUA | B3: 0 | C3: 0.72258046 | D3: Lysosomal Lumen
A4: NEU1 | B4: 0 | C4: 0.70894846 | D4: Lysosomal Lumen
A5: MAN2B1 | B5: 0 | C5: 0.70880052 | D5: Lysosomal Lumen
A6: NAGLU | B6: 0 | C6: 0.6790441 | D6: Lysosomal Lumen
A7: CPX-5675 | B7: 1 | C7: 1.5475136 | D7: Regulation Of Opsonization
A8: CPX-6215 | B8: 1 | C8: 1.4572379 | D8: Regulation Of Opsonization
A9: CPX-6234 | B9: 1 | C9: 1.4558477 | D9: Regulation Of Opsonization
A10: CPX-4945 | B10: 1 | C10: 1.3763838 | D10: Regulation Of Opsonization
A11: CPX-6224 | B11: 1 | C11: 1.3505542 | D11: Regulation Of Opsonization
A12: NRL | B12: 2 | C12: 0.77451374 | D12: Visual Perception
A13: GUCY2D | B13: 2 | C13: 0.73510789 | D13: Visual Perception
... A61: CPX-2296 | B61: 11 | C61: 1.0316847 | D61: PRC1 Complex

Sheet intercluster
A1: protein_name | B1: Clúster | C1: Intercluster_Connect_Score | D1: go_term
A2: FUCA1 | B2: 0 | C2: 1.598 | D2: Lysosomal Lumen
A3: IDS | B3: 0 | C3: 1.158 | D3: Lysosomal Lumen
A4: ARSB | B4: 0 | C4: 1.031 | D4: Lysosomal Lumen
A5: B4GALNT1 | B5: 0 | C5: 0.871 | D5: Lysosomal Lumen
A6: SGSH | B6: 0 | C6: 0.463 | D6: Lysosomal Lumen
A7: CPX-4945 | B7: 1 | C7: 4.126 | D7: Regulation Of Opsonization
A8: CPX-6223 | B8: 1 | C8: 4.086 | D8: Regulation Of Opsonization
A9: ADAMTS13 | B9: 1 | C9: 2.949 | D9: Regulation Of Opsonization
A10: SERPING1 | B10: 1 | C10: 1.874 | D10: Regulation Of Opsonization
A11: CPX-5602 | B11: 1 | C11: 1.618 | D11: Regulation Of Opsonization
A12: RPE65 | B12: 2 | C12: 17.32 | D12: Visual Perception
A13: CNGB1 | B13: 2 | C13: 11.184 | D13: Visual Perception
... A61: CPX-2297 | B61: 11 | C61: 52.128 | D61: PRC1 Complex

Sheet intracluster
A1: protein_name | B1: Clúster | C1: Intracluster_Connect_Score | D1: go_term
A2: GNS | B2: 0 | C2: 10.585 | D2: Lysosomal Lumen
A3: NAGLU | B3: 0 | C3: 10.574 | D3: Lysosomal Lumen
A4: CPX-502 | B4: 0 | C4: 9.758 | D4: Lysosomal Lumen
A5: CPX-687 | B5: 0 | C5: 9.7 | D5: Lysosomal Lumen
A6: CPX-686 | B6: 0 | C6: 9.195 | D6: Lysosomal Lumen
A7: CPX-6239 | B7: 1 | C7: 27.508 | D7: Regulation Of Opsonization
A8: CPX-6165 | B8: 1 | C8: 26.476 | D8: Regulation Of Opsonization
A9: SERPING1 | B9: 1 | C9: 25.392 | D9: Regulation Of Opsonization
A10: CPX-6179 | B10: 1 | C10: 25.254 | D10: Regulation Of Opsonization
A11: CPX-6240 | B11: 1 | C11: 25.052 | D11: Regulation Of Opsonization
A12: CRX | B12: 2 | C12: 37.587 | D12: Visual Perception
A13: RPE65 | B13: 2 | C13: 37.172 | D13: Visual Perception
... A61: CPX-7519 | B61: 11 | C61: 108.916 | D61: PRC1 Complex

Sheet raw
A1: Node_id | B1: Target_name | C1: Complex_participants | D1: Uniprot_id | E1: Target_type | F1: Target_group | G1: Source_db | H1: Target_group_score | I1: Target_group_score_normalized | J1: Conectivity_Score | K1: Disease
A2: CPX-289 | B2: glutamate nmda receptor; grin1/grin2a | C2: GRIN2D,GRIN1 | D2: O15399, Q05586 | E2: PROTEIN COMPLEX | F2: T1, T2, T3, T4 | G2: ChEMBL, STRING, TTD | H2: 16.1 | I2: 1 | K2: Alzheimer's Disease
A3: CPX-659 | B3: dna replication factor cdt1 (double parked homolog) (dup) | C3: CDT1,GMNN | D3: Q9H211, O75496 | E3: PROTEIN COMPLEX | F3: T1, T2, T3, T4 | G3: ChEMBL, STRING | H3: 16.1 | I3: 1 | K3: Alzheimer's Disease
A4: CPX-661 | B4: geminin | C4: GMNN,MCIDAS | D4: O75496, D6RGH6 | E4: PROTEIN COMPLEX | F4: T1, T2, T3, T4 | G4: ChEMBL, STRING | H4: 16.1 | I4: 1 | K4: Alzheimer's Disease
A5: CPX-702 | B5: nuclear receptor coactivator 2 (ncoa-2) (class e basic helix-loop-helix protein 75) (bhlhe75) (transcriptional intermediary factor 2) (htif2) | C5: NCOA2,PPARG | D5: Q15596, P37231 | E5: PROTEIN COMPLEX | F5: T1, T2, T3, T4 | G5: ChEMBL, STRING, TTD | H5: 16.1 | I5: 1 | K5: Alzheimer's Disease
A6: CPX-711 | B6: nuclear receptor coactivator 1 (ncoa-1) (ec 2.3.1.48) (class e basic helix-loop-helix protein 74) (bhlhe74) (protein hin-2) (rip160) (renal carcinoma antigen ny-ren-52) (steroid receptor coactivator 1) (src-1) | C6: NCOA1,PPARG | D6: Q15788, P37231 | E6: PROTEIN COMPLEX | F6: T1, T2, T3, T4 | G6: ChEMBL, STRING, TTD | H6: 16.1 | I6: 1 | K6: Alzheimer's Disease
A7: CPX-793 | B7: aprataxin (ec 3.6.1.71) (ec 3.6.1.72) (forkhead-associated domain histidine triad-like protein) (fha-hit) | C7: LIG3,XRCC1,TDP1,APLF,POLB,APTX,PNKP | D7: P49916, P18887, Q9NUW8, Q8IW19, P06746, Q7Z2E3, Q96T60 | E7: PROTEIN COMPLEX | F7: T1, T2, T3, T4 | G7: ChEMBL, STRING | H7: 16.1 | I7: 1 | K7: Alzheimer's Disease
A8: CPX-6094 | B8: geminin | C8: GMNN,HOXD10 | D8: O75496, P28358 | E8: PROTEIN COMPLEX | F8: T1, T2, T3, T4 | G8: ChEMBL, STRING | H8: 16.1 | I8: 1 | K8: Alzheimer's Disease
A9: ACHE | B9: acetylcholinesterase | D9: P22303 | E9: SINGLE PROTEIN | F9: T1, T2, T3 | G9: ChEMBL, TTD | H9: 16 | I9: 0.994375 | K9: Alzheimer's Disease
A10: CBX1 | B10: chromobox protein homolog 1 | D10: P83916 | E10: SINGLE PROTEIN | F10: T1, T2, T3 | G10: ChEMBL | H10: 16 | I10: 0.994375 | K10: Alzheimer's Disease
A11: CPX-285 | B11: glutamate [nmda] receptor subunit epsilon 2 | C11: GRIN2B,GRIN1 | D11: Q13224, Q05586 | E11: PROTEIN COMPLEX | F11: T1, T2, T3 | G11: ChEMBL, TTD | H11: 16 | I11: 0.994375 | K11: Alzheimer's Disease
A12: CPX-286 | B12: glutamate nmda receptor; grin1/grin2a | C12: GRIN1,GRIN2C | D12: Q05586, Q14957 | E12: PROTEIN COMPLEX | F12: T1, T2, T3 | G12: ChEMBL, TTD | H12: 16 | I12: 0.994375 | K12: Alzheimer's Disease
A13: CPX-294 | B13: glutamate [nmda] receptor subunit epsilon 2 | C13: GRIN1,GRIN2A,GRIN2B | D13: Q05586, Q12879, Q13224 | E13: PROTEIN COMPLEX | F13: T1, T2, T3 | G13: ChEMBL, TTD | H13: 16 | I13: 0.994375 | K13: Alzheimer's Disease
A14: CPX-660 | B14: geminin | C14: GMNN,HOXC9 | D14: O75496, P31274 | E14: PROTEIN COMPLEX | F14: T1, T2, T3 | G14: ChEMBL | H14: 16 | I14: 0.994375 | K14: Alzheimer's Disease
A15: CPX-1062 | B15: amyloid beta a4 protein (app) | C15: P05067-PRO_0000000092,P05067-PRO_0000000093 | D15: P05067, P05067 | E15: PROTEIN COMPLEX | F15: T1, T2, T3 | G15: ChEMBL, TTD | H15: 16 | I15: 0.994375 | K15: Alzheimer's Disease
A16: CPX-1069 | B16: amyloid beta a4 protein (app) | C16: P05067-PRO_0000000093 | D16: P05067 | E16: PROTEIN COMPLEX | F16: T1, T2, T3 | G16: ChEMBL, TTD | H16: 16 | I16: 0.994375 | K16: Alzheimer's Disease
A17: CPX-1070 | B17: amyloid beta a4 protein (app) | C17: P05067-PRO_0000000092 | D17: P05067 | E17: PROTEIN COMPLEX | F17: T1, T2, T3 | G17: ChEMBL, TTD | H17: 16 | I17: 0.994375 | K17: Alzheimer's Disease
A18: CPX-1120 | B18: amyloid beta a4 protein (app) | C18: P05067-PRO_0000000092,P05067-PRO_0000000093 | D18: P05067, P05067 | E18: PROTEIN COMPLEX | F18: T1, T2, T3 | G18: ChEMBL, TTD | H18: 16 | I18: 0.994375 | K18: Alzheimer's Disease
A19: CPX-1134 | B19: amyloid beta a4 protein (app) | C19: P05067-PRO_0000000092 | D19: P05067 | E19: PROTEIN COMPLEX | F19: T1, T2, T3 | G19: ChEMBL, TTD | H19: 16 | I19: 0.994375 | K19: Alzheimer's Disease
A20: CPX-1180 | B20: amyloid beta a4 protein (app) | C20: P05067-PRO_0000000093 | D20: P05067 | E20: PROTEIN COMPLEX | F20: T1, T2, T3 | G20: ChEMBL, TTD | H20: 16 | I20: 0.994375 | K20: Alzheimer's Disease
A21: CPX-2202 | B21: glutamate nmda receptor; grin1/grin2a | C21: GRIN1,GRIN2A | D21: Q05586, Q12879 | E21: PROTEIN COMPLEX | F21: T1, T2, T3 | G21: ChEMBL, TTD | H21: 16 | I21: 0.994375 | K21: Alzheimer's Disease
A22: DRD2 | B22: dopamine d2 receptor | D22: P14416 | E22: SINGLE PROTEIN | F22: T1, T2, T3 | G22: ChEMBL, TTD | H22: 16 | I22: 0.994375 | K22: Alzheimer's Disease
A23: EHMT2 | B23: histone-lysine n-methyltransferase, h3 lysine-9 specific 3 | D23: Q96KQ7 | E23: SINGLE PROTEIN | F23: T1, T2, T3 | G23: ChEMBL | H23: 16 | I23: 0.994375 | K23: Alzheimer's Disease
A24: HRH3 | B24: histamine h3 receptor | D24: Q9Y5N1 | E24: SINGLE PROTEIN | F24: T1, T2, T3 | G24: ChEMBL, TTD | H24: 16 | I24: 0.994375 | K24: Alzheimer's Disease
A25: KDM4E | B25: lysine-specific demethylase 4d-like | D25: B2RXH2 | E25: SINGLE PROTEIN | F25: T1, T2, T3 | G25: ChEMBL | H25: 16 | I25: 0.994375 | K25: Alzheimer's Disease
A26: LMNA | B26: prelamin-a/c | D26: P02545 | E26: SINGLE PROTEIN | F26: T1, T2, T3 | G26: ChEMBL | H26: 16 | I26: 0.994375 | K26: Alzheimer's Disease
A27: SLC6A4 | B27: serotonin transporter | D27: P31645 | E27: SINGLE PROTEIN | F27: T1, T2, T3 | G27: ChEMBL, TTD | H27: 16 | I27: 0.994375 | K27: Alzheimer's Disease
A28: SLCO1B1 | B28: solute carrier organic anion transporter family member 1b1 | D28: Q9Y6L6 | E28: SINGLE PROTEIN | F28: T1, T2, T3 | G28: ChEMBL | H28: 16 | I28: 0.994375 | K28: Alzheimer's Disease
A29: SLCO1B3 | B29: solute carrier organic anion transporter family member 1b3 | D29: Q9NPD5 | E29: SINGLE PROTEIN | F29: T1, T2, T3 | G29: ChEMBL | H29: 16 | I29: 0.994375 | K29: Alzheimer's Disease
A30: USP1 | B30: ubiquitin carboxyl-terminal hydrolase 1 | D30: O94782 | E30: SINGLE PROTEIN | F30: T1, T2, T3 | G30: ChEMBL | H30: 16 | I30: 0.994375 | K30: Alzheimer's Disease
A31: BCHE | B31: butyrylcholinesterase | D31: P06276 | E31: SINGLE PROTEIN | F31: T1, T2 | G31: ChEMBL, TTD | H31: 15 | I31: 0.938125 | K31: Alzheimer's Disease
A32: CPX-255 | B32: acetylcholine receptor protein epsilon chain | C32: CHRND,Q04844-PRO_0000000329,P02708-PRO_0000000305,P11230-PRO_0000000315 | D32: Q07001, Q04844, P02708, P11230 | E32: PROTEIN COMPLEX | F32: T1, T2 | G32: ChEMBL | H32: 15 | I32: 0.938125 | K32: Alzheimer's Disease
A33: DYRK1A | B33: dual-specificity tyrosine-phosphorylation regulated kinase 1a | D33: Q13627 | E33: SINGLE PROTEIN | F33: T1, T2 | G33: ChEMBL | H33: 15 | I33: 0.938125 | K33: Alzheimer's Disease
A34: DYRK2 | B34: dual-specificity tyrosine-phosphorylation regulated kinase 2 | D34: Q92630 | E34: SINGLE PROTEIN | F34: T1, T2 | G34: ChEMBL | H34: 15 | I34: 0.938125 | K34: Alzheimer's Disease
A35: IDH1 | B35: isocitrate dehydrogenase [nadp] cytoplasmic | D35: O75874 | E35: SINGLE PROTEIN | F35: T1, T2 | G35: ChEMBL | H35: 15 | I35: 0.938125 | K35: Alzheimer's Disease
A36: NPSR1 | B36: neuropeptide s receptor | D36: Q6W5P4 | E36: SINGLE PROTEIN | F36: T1, T2 | G36: ChEMBL | H36: 15 | I36: 0.938125 | K36: Alzheimer's Disease
A37: PMP22 | B37: peripheral myelin protein 22 | D37: Q01453 | E37: SINGLE PROTEIN | F37: T1, T2 | G37: ChEMBL | H37: 15 | I37: 0.938125 | K37: Alzheimer's Disease
A38: PTH1R | B38: parathyroid hormone receptor | D38: Q03431 | E38: SINGLE PROTEIN | F38: T1, T2 | G38: ChEMBL | H38: 15 | I38: 0.938125 | K38: Alzheimer's Disease
A39: TRPV1 | B39: vanilloid receptor | D39: Q8NER1 | E39: SINGLE PROTEIN | F39: T1, T2 | G39: ChEMBL | H39: 15 | I39: 0.938125 | K39: Alzheimer's Disease
A40: CPX-1 | B40: mothers against decapentaplegic homolog 2 | C40: SMAD4,SMAD2,SMAD3 | D40: Q13485, Q15796, P84022 | E40: PROTEIN COMPLEX | F40: T2, T3, T4 | G40: ChEMBL, STRING | H40: 6.1 | I40: 0.4375 | K40: Alzheimer's Disease
...

Sheet T4_metrics
A1: Nombre proteína | B1: Target_group | C1: Cluster_label | D1: intracluster connect | E1: intercluster connect | F1: Conectivity_Score | G1: Termino GO
A2: CPX-1209 | B2: T4 | C2: 10 | D2: 39.226 | E2: 169.223 | F2: 1.3194661 | G2: nBAF Complex
A3: CPX-1216 | B3: T4 | C3: 10 | D3: 39.226 | E3: 169.223 | F3: 1.4328376 | G3: nBAF Complex
A4: CPX-1219 | B4: T4 | C4: 10 | D4: 39.226 | E4: 169.223 | F4: 1.3189422 | G4: nBAF Complex
A5: CPX-1226 | B5: T4 | C5: 10 | D5: 39.226 | E5: 169.223 | F5: 1.3194661 | G5: nBAF Complex
A6: CPX-1202 | B6: T4 | C6: 10 | D6: 39.644 | E6: 169.114 | F6: 1.4178513 | G6: nBAF Complex
A7: CPX-1203 | B7: T4 | C7: 10 | D7: 39.644 | E7: 169.114 | F7: 1.3051482 | G7: nBAF Complex
A8: CPX-1207 | B8: T4 | C8: 10 | D8: 39.644 | E8: 169.114 | F8: 1.3056945 | G8: nBAF Complex
A9: CPX-1225 | B9: T4 | C9: 10 | D9: 39.644 | E9: 169.114 | F9: 1.3056945 | G9: nBAF Complex
A10: CPX-1195 | B10: T4 | C10: 10 | D10: 39.226 | E10: 168.796 | F10: 1.2518859 | G10: nBAF Complex
A11: CPX-1204 | B11: T4 | C11: 10 | D11: 39.226 | E11: 168.774 | F11: 1.1963229 | G11: nBAF Complex
A12: CPX-1212 | B12: T4 | C12: 10 | D12: 39.226 | E12: 168.774 | F12: 1.1958308 | G12: nBAF Complex
A13: CPX-1222 | B13: T4 | C13: 10 | D13: 39.226 | E13: 168.774 | F13: 0.94145284 | G13: nBAF Complex
... A693: CPX-8641 | B693: T4 | C693: 5 | D693: 145.803 | E693: 0 | F693: 0.89132601 | G693: Anterograde Trans-Synaptic Signaling
